2020-08-01 22:15:13,963 INFO     root            Simulation playing
2020-08-01 22:15:13,963 INFO     root            step started
2020-08-01 22:15:13,964 INFO     root            step done
2020-08-01 22:15:13,964 ERROR    concurrent.futures exception calling callback for <Future at 0x1f47a63d7c8 state=finished returned NoneType>
Traceback (most recent call last):
  File "C:\Users\andre\Anaconda3\lib\concurrent\futures\_base.py", line 324, in _invoke_callbacks
    callback(self)
TypeError: callback() takes 0 positional arguments but 1 was given
2020-08-01 22:15:16,116 INFO     root            Simulation playing
2020-08-01 22:15:16,116 INFO     root            step started
2020-08-01 22:15:16,116 INFO     root            step done
2020-08-01 22:15:16,116 ERROR    concurrent.futures exception calling callback for <Future at 0x1f47a63d888 state=finished returned NoneType>
Traceback (most recent call last):
  File "C:\Users\andre\Anaconda3\lib\concurrent\futures\_base.py", line 324, in _invoke_callbacks
    callback(self)
TypeError: callback() takes 0 positional arguments but 1 was given
2020-08-01 22:15:16,648 INFO     root            Simulation playing
2020-08-01 22:15:16,648 INFO     root            step started
2020-08-01 22:15:16,648 INFO     root            step done
2020-08-01 22:15:16,648 ERROR    concurrent.futures exception calling callback for <Future at 0x1f47a63d7c8 state=finished returned NoneType>
Traceback (most recent call last):
  File "C:\Users\andre\Anaconda3\lib\concurrent\futures\_base.py", line 324, in _invoke_callbacks
    callback(self)
TypeError: callback() takes 0 positional arguments but 1 was given
2020-08-01 22:15:16,914 INFO     root            Simulation playing
2020-08-01 22:15:16,914 INFO     root            step started
2020-08-01 22:15:16,914 INFO     root            step done
2020-08-01 22:15:16,914 ERROR    concurrent.futures exception calling callback for <Future at 0x1f47a63d888 state=finished returned NoneType>
Traceback (most recent call last):
  File "C:\Users\andre\Anaconda3\lib\concurrent\futures\_base.py", line 324, in _invoke_callbacks
    callback(self)
TypeError: callback() takes 0 positional arguments but 1 was given
2020-08-01 22:15:17,224 INFO     root            Simulation playing
2020-08-01 22:15:17,224 INFO     root            step started
2020-08-01 22:15:17,224 INFO     root            step done
2020-08-01 22:15:17,224 ERROR    concurrent.futures exception calling callback for <Future at 0x1f47a63d7c8 state=finished returned NoneType>
Traceback (most recent call last):
  File "C:\Users\andre\Anaconda3\lib\concurrent\futures\_base.py", line 324, in _invoke_callbacks
    callback(self)
TypeError: callback() takes 0 positional arguments but 1 was given
2020-08-01 22:15:17,399 INFO     root            Simulation playing
2020-08-01 22:15:17,399 INFO     root            step started
2020-08-01 22:15:17,399 INFO     root            step done
2020-08-01 22:15:17,399 ERROR    concurrent.futures exception calling callback for <Future at 0x1f47a63d888 state=finished returned NoneType>
Traceback (most recent call last):
  File "C:\Users\andre\Anaconda3\lib\concurrent\futures\_base.py", line 324, in _invoke_callbacks
    callback(self)
TypeError: callback() takes 0 positional arguments but 1 was given
2020-08-01 22:15:17,564 INFO     root            Simulation playing
2020-08-01 22:15:17,564 INFO     root            step started
2020-08-01 22:15:17,564 INFO     root            step done
2020-08-01 22:15:17,564 ERROR    concurrent.futures exception calling callback for <Future at 0x1f47a63d7c8 state=finished returned NoneType>
Traceback (most recent call last):
  File "C:\Users\andre\Anaconda3\lib\concurrent\futures\_base.py", line 324, in _invoke_callbacks
    callback(self)
TypeError: callback() takes 0 positional arguments but 1 was given
2020-08-01 22:15:17,723 INFO     root            Simulation playing
2020-08-01 22:15:17,723 INFO     root            step started
2020-08-01 22:15:17,723 INFO     root            step done
2020-08-01 22:15:17,723 ERROR    concurrent.futures exception calling callback for <Future at 0x1f47a63d888 state=finished returned NoneType>
Traceback (most recent call last):
  File "C:\Users\andre\Anaconda3\lib\concurrent\futures\_base.py", line 324, in _invoke_callbacks
    callback(self)
TypeError: callback() takes 0 positional arguments but 1 was given
2020-08-01 22:15:19,294 INFO     root            Exiting...
